<?xml version="1.0"?>
<robot name="02-stl-move" xmlns:xacro="http://ros.org/wiki.xacro">
  <xacro:property name="width" value="0.5"/>

  <material name="blue">
    <color rgba="0 0 0.8 1"/>
  </material>
  <material name="green">
    <color rgba="0 0.8 0 1"/>
  </material>
  <material name="red">
    <color rgba="0.8 0 0 1"/>
  </material>
  <material name="white">
    <color rgba="0.8 0.8 0.8 1"/>
  </material>

  <xacro:property name="mesh_dir"
      value="package://spider_capstone_description/meshes"/>
  <xacro:property name="mesh_scale" value="0.001"/>
  <xacro:property name="offset_scale" value="150"/>

  <!--  The Base  -->
  <link name="base_link">
    <visual>
      <geometry>
        <box size="0.02 0.03 0.01"/>
      </geometry>
    </visual>
  </link>
  
  <joint name="shoulder base" type="fixed">
    <parent link="base_link"/>
    <child link="shoulder_base"/>
    <origin xyz="0.01 0.015 0" rpy="0 0 ${pi/4}"/>
  </joint>

  <!--  The Leg   -->
  <link name="shoulder_base">
    <visual>
      <geometry>
        <mesh filename="${mesh_dir}/MockBase.stl" scale="${mesh_scale} ${mesh_scale} ${mesh_scale}"/>
      </geometry>
      <origin xyz="0.08 -0.02 0.04" rpy="${-pi/2} 0 ${pi/2}"/>
      <material name="blue"/>
    </visual>
  </link>
  
  <link name="Link1">
    <visual>
      <geometry>
        <mesh filename="${mesh_dir}/Link1.stl" scale="${mesh_scale} ${mesh_scale} ${mesh_scale}"/>
      </geometry>
      <origin xyz="-0.011 0.011 -0.02" rpy="${pi/2} 0 0"/>
      <material name="green"/>
    </visual>
  </link>

  <joint name="shoulder" type="revolute">
    <axis xyz="0 0 1"/>
    <limit effort="1000" lower="${-pi/4}" upper="${pi/4}" velocity="0.5"/>
    <parent link="shoulder_base"/>
    <child link="Link1"/>
    <origin xyz="0.07 0 0.04" rpy="0 0 0"/>
  </joint>

  <link name="Link2">
    <visual>
     <geometry>
       <mesh filename="${mesh_dir}/Link2.stl" scale="${mesh_scale} ${mesh_scale} ${mesh_scale}"/>
     </geometry> 
     <origin xyz="-0.011 0.011 -0.02" rpy="${pi/2} 0 0"/>
     <material name="red"/>
    </visual>
  </link>

  <joint name="elbow" type="revolute">
    <axis xyz="0 0 1"/>
    <limit effort="1000" lower="${-pi/4}" upper="${pi/4}" velocity="0.5"/>
    <parent link="Link1"/>
    <child link="Link2"/>
    <origin xyz="0.092 0 0" rpy="${-pi/2} 0 0"/>
  </joint>

  <link name="Link3">
    <visual>
      <geometry>
        <mesh filename="${mesh_dir}/Link3.stl" scale="${mesh_scale} ${mesh_scale} ${mesh_scale}"/>
      </geometry>
      <origin xyz="-0.01 0.03 -0.025" rpy="${pi/2} 0 0"/>
      <material name="white"/>
    </visual>
  </link>

  <joint name="wrist" type="revolute">
    <axis xyz="0 0 1"/>
    <limit effort="1000" lower="${-pi/4}" upper="${pi/4}" velocity="0.5"/>
    <parent link="Link2"/>
    <child link="Link3"/>
    <origin xyz="0.092 0 0.005" rpy="0 0 0"/>
  </joint>

</robot>
