<?xml version="1.0"?>
<!--URDF generated by ONSHAPE BY PTC INC, 1.213-->
<robot name="spider" xmlns:xacro="http://www.ros.org/wiki/xacro">
    <xacro:macro name="leg" params="prefix *sh_orig">
        <!--  Create first joint  -->
        <joint name="base_plate_2_${prefix}" type="fixed">
            <parent link="BaseLowerPlate"/>
            <child link="${prefix}_mg90s_body_1_solid1"/>
            <xacro:insert_block name="sh_orig"/>
        </joint>

        <link name="${prefix}_claw_tip">
            <inertial>
                <mass value="1.75677e-05" />
                <origin xyz="0.00127 0.022498 -0.0143189" rpy="0 -0 0" />
                <inertia ixx="3.68089e-09" ixy="0" ixz="0" iyy="1.45631e-09" iyz="4.9792e-10" izz="3.42152e-09" />
            </inertial>
            <visual>
                <origin xyz="0.00127 -0.181123 -0.03175" rpy="0 -0 0" />
                <geometry>
                    <mesh filename="package://spider_capstone_description/meshes/V2/claw tip.stl" scale="1 1 1" />
                </geometry>
                <material name="0.796078_0.823529_0.937255_0.000000_0.000000">
                    <texture />
                    <color rgba="0.796078 0.823529 0.937255 1" />
                </material>
            </visual>
        </link>
        <link name="${prefix}_link_1">
            <inertial>
                <mass value="1.79054e-05" />
                <origin xyz="-0.000826111 0.0217206 -0.0190256" rpy="0 -0 0" />
                <inertia ixx="9.35956e-09" ixy="2.83487e-10" ixz="1.69011e-10" iyy="6.31112e-09" iyz="-5.92444e-10" izz="4.88763e-09" />
            </inertial>
            <visual>
                <origin xyz="-7.95199e-19 -4.87891e-19 -0.00188" rpy="0 -0 0" />
                <geometry>
                    <mesh filename="package://spider_capstone_description/meshes/V2/Link 1.stl" scale="1 1 1" />
                </geometry>
                <material name="0.796078_0.823529_0.937255_0.000000_0.000000">
                    <texture />
                    <color rgba="0.796078 0.823529 0.937255 1" />
                </material>
            </visual>
        </link>
        <link name="${prefix}_link_2">
            <inertial>
                <mass value="3.51642e-05" />
                <origin xyz="-0.0271895 -0.00292913 0.00223503" rpy="0 -0 0" />
                <inertia ixx="2.57771e-08" ixy="3.45112e-10" ixz="8.67221e-11" iyy="1.83907e-08" iyz="1.18192e-09" izz="3.85571e-08" />
            </inertial>
            <visual>
                <origin xyz="-0.0289508 -0.0968311 -1.69136e-17" rpy="0 -0 0" />
                <geometry>
                    <mesh filename="package://spider_capstone_description/meshes/V2/Link 2.stl" scale="1 1 1" />
                </geometry>
                <material name="0.615686_0.811765_0.929412_0.000000_0.000000">
                    <texture />
                    <color rgba="0.615686 0.811765 0.929412 1" />
                </material>
            </visual>
        </link>
        <link name="${prefix}_link_3">
            <inertial>
                <mass value="1.98758e-05" />
                <origin xyz="-0.0212036 0.0226404 0.00349567" rpy="0 -0 0" />
                <inertia ixx="6.13545e-09" ixy="2.45391e-11" ixz="6.38731e-11" iyy="5.96934e-09" iyz="-9.06578e-10" izz="7.75081e-09" />
            </inertial>
            <visual>
                <origin xyz="-0.0189797 -0.14 -1.95117e-17" rpy="0 -0 0" />
                <geometry>
                    <mesh filename="package://spider_capstone_description/meshes/V2/Link 3.stl" scale="1 1 1" />
                </geometry>
                <material name="0.796078_0.823529_0.937255_0.000000_0.000000">
                    <texture />
                    <color rgba="0.796078 0.823529 0.937255 1" />
                </material>
            </visual>
        </link>
        <link name="${prefix}_mg90s_body_1_solid1">
            <inertial>
                <mass value="7.293e-06" />
                <origin xyz="0.00499948 6.12411e-10 -0.0152918" rpy="0 -0 0" />
                <inertia ixx="5.03315e-10" ixy="1.25043e-13" ixz="3.47219e-11" iyy="7.56418e-10" iyz="0" izz="4.25325e-10" />
            </inertial>
            <visual>
                <origin xyz="-8.67362e-19 -4.87891e-19 0.0036" rpy="0 -0 0" />
                <geometry>
                    <mesh filename="package://spider_capstone_description/meshes/V2/MG90S Body_1_solid1.stl" scale="1 1 1" />
                </geometry>
                <material name="0.796078_0.823529_0.937255_0.000000_0.000000">
                    <texture />
                    <color rgba="0.796078 0.823529 0.937255 1" />
                </material>
            </visual>
        </link>
        <link name="${prefix}_mg90s_body_1_solid1_1">
            <inertial>
                <mass value="7.293e-06" />
                <origin xyz="-0.00189181 6.12411e-10 0.0141505" rpy="0 -0 0" />
                <inertia ixx="4.25325e-10" ixy="0" ixz="-3.47219e-11" iyy="7.56418e-10" iyz="-1.25043e-13" izz="5.03315e-10" />
            </inertial>
            <visual>
                <origin xyz="-9.969e-05 -0.14 0.01915" rpy="0 -0 0" />
                <geometry>
                    <mesh filename="package://spider_capstone_description/meshes/V2/MG90S Body_1_solid1_1.stl" scale="1 1 1" />
                </geometry>
                <material name="0.796078_0.823529_0.937255_0.000000_0.000000">
                    <texture />
                    <color rgba="0.796078 0.823529 0.937255 1" />
                </material>
            </visual>
        </link>
        <link name="${prefix}_mg90s_top_1_solid2">
            <inertial>
                <mass value="2.92444e-07" />
                <origin xyz="0.00361718 0.00530087 -3.56276e-06" rpy="0 -0 0" />
                <inertia ixx="1.1265e-11" ixy="-2.93582e-13" ixz="0" iyy="1.42748e-12" iyz="6.10276e-15" izz="1.05075e-11" />
            </inertial>
            <visual>
                <origin xyz="-0.0134997 -0.14 -1.18099e-16" rpy="0 -0 0" />
                <geometry>
                    <mesh filename="package://spider_capstone_description/meshes/V2/MG90S Top_1_solid2.stl" scale="1 1 1" />
                </geometry>
                <material name="0.796078_0.823529_0.937255_0.000000_0.000000">
                    <texture />
                    <color rgba="0.796078 0.823529 0.937255 1" />
                </material>
            </visual>
        </link>
        <link name="${prefix}_mg90s_top_1_solid2_1">
            <inertial>
                <mass value="2.92444e-07" />
                <origin xyz="3.56276e-06 0.00530087 -0.00218282" rpy="0 -0 0" />
                <inertia ixx="1.05075e-11" ixy="-6.10276e-15" ixz="0" iyy="1.42748e-12" iyz="-2.93582e-13" izz="1.1265e-11" />
            </inertial>
            <visual>
                <origin xyz="9.97466e-17 -4.87891e-19 -0.0022" rpy="0 -0 0" />
                <geometry>
                    <mesh filename="package://spider_capstone_description/meshes/V2/MG90S Top_1_solid2_1.stl" scale="1 1 1" />
                </geometry>
                <material name="0.796078_0.823529_0.937255_0.000000_0.000000">
                    <texture />
                    <color rgba="0.796078 0.823529 0.937255 1" />
                </material>
            </visual>
        </link>
        <link name="${prefix}_mg995r">
            <inertial>
                <mass value="3.01951e-05" />
                <origin xyz="0.00867353 -0.005 -0.0241102" rpy="0 -0 0" />
                <inertia ixx="5.11798e-09" ixy="0" ixz="2.35098e-11" iyy="7.6641e-09" iyz="0" izz="4.50643e-09" />
            </inertial>
            <visual>
                <origin xyz="0.00899404 -0.055 -0.01415" rpy="0 -0 0" />
                <geometry>
                    <mesh filename="package://spider_capstone_description/meshes/V2/MG995R.stl" scale="1 1 1" />
                </geometry>
                <material name="0.301961_0.301961_0.301961_0.000000_0.000000">
                    <texture />
                    <color rgba="0.301961 0.301961 0.301961 1" />
                </material>
            </visual>
        </link>
        <link name="${prefix}_mg995r_axel">
            <inertial>
                <mass value="3.86986e-07" />
                <origin xyz="0.00327734 -5.90777e-14 2.29869e-14" rpy="0 -0 0" />
                <inertia ixx="1.8665e-12" ixy="0" ixz="0" iyy="8.52487e-12" iyz="0" izz="8.52487e-12" />
            </inertial>
            <visual>
                <origin xyz="0.019494 -0.05 4.93038e-35" rpy="0 -0 0" />
                <geometry>
                    <mesh filename="package://spider_capstone_description/meshes/V2/MG995R_axel.stl" scale="1 1 1" />
                </geometry>
                <material name="0.796078_0.823529_0.937255_0.000000_0.000000">
                    <texture />
                    <color rgba="0.796078 0.823529 0.937255 1" />
                </material>
            </visual>
        </link>
        <link name="${prefix}_mg996r_seat">
            <inertial>
                <mass value="3.09262e-06" />
                <origin xyz="0.000849309 -7.98706e-05 0.00113553" rpy="0 -0 0" />
                <inertia ixx="6.96578e-10" ixy="-3.64102e-13" ixz="-7.82475e-12" iyy="5.39489e-10" iyz="9.73697e-15" izz="1.74173e-10" />
            </inertial>
            <visual>
                <origin xyz="-0.019 -0.05 0.0112682" rpy="0 -0 0" />
                <geometry>
                    <mesh filename="package://spider_capstone_description/meshes/V2/MG996R_Seat.stl" scale="1 1 1" />
                </geometry>
                <material name="0.796078_0.823529_0.937255_0.000000_0.000000">
                    <texture />
                    <color rgba="0.796078 0.823529 0.937255 1" />
                </material>
            </visual>
        </link>
        <link name="${prefix}_mg996r_seat_pin">
            <inertial>
                <mass value="7.20083e-06" />
                <origin xyz="0.0112698 0.019388 0.000827221" rpy="0 -0 0" />
                <inertia ixx="2.87289e-09" ixy="-9.50747e-11" ixz="-4.05652e-12" iyy="3.86681e-10" iyz="-3.07331e-11" izz="2.57297e-09" />
            </inertial>
            <visual>
                <origin xyz="-0.019 -0.05 -1.73472e-17" rpy="0 -0 0" />
                <geometry>
                    <mesh filename="package://spider_capstone_description/meshes/V2/MG996R_seat_pin.stl" scale="1 1 1" />
                </geometry>
                <material name="0.972549_0.529412_0.003922_0.000000_0.000000">
                    <texture />
                    <color rgba="0.972549 0.529412 0.00392157 1" />
                </material>
            </visual>
        </link>
        <link name="${prefix}_small_servo_seat">
            <inertial>
                <mass value="1.48627e-06" />
                <origin xyz="-0.000500124 -0.00691528 -0.000514238" rpy="0 -0 0" />
                <inertia ixx="5.16975e-11" ixy="-8.46893e-14" ixz="1.37536e-12" iyy="1.08149e-10" iyz="3.11281e-13" izz="1.5424e-10" />
            </inertial>
            <visual>
                <origin xyz="-0.0053 -0.006508 0.0322" rpy="0 -0 0" />
                <geometry>
                    <mesh filename="package://spider_capstone_description/meshes/V2/small servo seat.stl" scale="1 1 1" />
                </geometry>
                <material name="0.796078_0.823529_0.937255_0.000000_0.000000">
                    <texture />
                    <color rgba="0.796078 0.823529 0.937255 1" />
                </material>
            </visual>
        </link>
        <joint name="${prefix}_fastened_10_0" type="fixed">
            <origin xyz="-0.0289511 0.0431689 -0.01915" rpy="0 0 -4.1601e-46" />
            <axis xyz="1 3.40103e-16 3.98986e-16" />
            <parent link="${prefix}_link_2" />
            <child link="${prefix}_mg90s_body_1_solid1_1" />
        </joint>

        <joint name="${prefix}_fastened_2_0" type="fixed">
            <origin xyz="0.0047 0.0058 -0.0286" rpy="0 -0 0" />
            <axis xyz="1 0 0" />
            <parent link="${prefix}_mg90s_body_1_solid1" />
            <child link="${prefix}_small_servo_seat" />
        </joint>
        <joint name="${prefix}_fastened_3_0" type="fixed">
            <origin xyz="-0.0202497 0.0411228 0.03175" rpy="2.66283e-10 -2.01625e-16 5.55112e-17" />
            <axis xyz="-2.23198e-16 1 -5.32569e-10" />
            <parent link="${prefix}_link_3" />
            <child link="${prefix}_claw_tip" />
        </joint>
        <joint name="${prefix}_fastened_4_0" type="fixed">
            <origin xyz="0.0058 2.77556e-17 3.46945e-18" rpy="1.1497e-25 -4.3176e-16 -5.82867e-16" />
            <axis xyz="1 3.40103e-16 3.98986e-16" />
            <parent link="${prefix}_mg90s_top_1_solid2" />
            <child link="${prefix}_link_3" />
        </joint>
        <joint name="${prefix}_fastened_5_0" type="fixed">
            <origin xyz="-0.00879404 0.055 0.01227" rpy="5.16168e-25 -6.83526e-18 -5.32569e-10" />
            <axis xyz="-1 -3.40103e-16 6.83526e-18" />
            <parent link="${prefix}_link_1" />
            <child link="${prefix}_mg995r" />
        </joint>
        <joint name="${prefix}_fastened_6_0" type="fixed">
            <origin xyz="1.0842e-19 1.0842e-19 -8.67362e-19" rpy="-5.20793e-18 -1.23722e-19 -2.77556e-17" />
            <axis xyz="0 0 1" />
            <parent link="${prefix}_link_1" />
            <child link="${prefix}_mg90s_top_1_solid2_1" />
        </joint>
        <joint name="${prefix}_fastened_7_0" type="fixed">
            <origin xyz="0.027994 -0.005 -0.02415" rpy="2.12375e-26 -2.34857e-18 -5.55111e-17" />
            <axis xyz="1 3.40103e-16 3.98986e-16" />
            <parent link="${prefix}_mg995r" />
            <child link="${prefix}_mg996r_seat" />
        </joint>
        <joint name="${prefix}_fastened_8_0" type="fixed">
            <origin xyz="-0.012 -0.005 -0.01415" rpy="4.54002e-32 -3.0006e-31 -5.55112e-17" />
            <axis xyz="-1 -3.40103e-16 -9.86076e-32" />
            <parent link="${prefix}_mg995r" />
            <child link="${prefix}_mg995r_axel" />
        </joint>
        <joint name="${prefix}_fastened_9_0" type="fixed">
            <origin xyz="0.00995077 0.0468311 0" rpy="0 0 -4.1601e-46" />
            <axis xyz="-1 0 0" />
            <parent link="${prefix}_mg996r_seat_pin" />
            <child link="${prefix}_link_2" />
        </joint>
        <joint name="${prefix}_hip" type="continuous">
            <origin xyz="-0.0053 -0.006508 0.03408" rpy="5.37143e-25 -1.6899e-25 -4.77163e-50" />
            <axis xyz="0 0 1" />
            <parent link="${prefix}_small_servo_seat" />
            <child link="${prefix}_link_1" />
        </joint>
        <joint name="${prefix}_knee" type="continuous">
            <origin xyz="5.13478e-16 3.19189e-16 0.0112682" rpy="-2.498e-15 6.80837e-17 1.01795e-16" />
            <axis xyz="-1 0 0" />
            <parent link="${prefix}_mg996r_seat" />
            <child link="${prefix}_mg996r_seat_pin" />
        </joint>
        <joint name="${prefix}_ankle" type="continuous">
            <origin xyz="0.0134 5.55112e-17 0.01915" rpy="3.55271e-15 -1.5812e-25 -6.12323e-17" />
            <axis xyz="-1 3.40103e-16 3.98986e-16" />
            <parent link="${prefix}_mg90s_body_1_solid1_1" />
            <child link="${prefix}_mg90s_top_1_solid2" />
        </joint>

        <joint name="${prefix}_claw_2_end_effector" type="fixed">
            <origin xyz="0.001 0.064 -0.0315"/>
            <parent link="${prefix}_claw_tip"/>
            <child link="${prefix}_end_effector"/>
        </joint>

        <link name="${prefix}_end_effector">
            <visual>
              <geometry>
                <sphere radius="0.001"/>
              </geometry>
            </visual>
          </link>
    </xacro:macro>
</robot>
